Workbook

Sheet Read Me
A1: Meals Acceptance Checklist
A2: Requirements baseline | B2: Meals Module Product & Functional Requirements v0.3
A3: Purpose | B3: Track functional, end-to-end, security, and database acceptance against stable requirement IDs.
A5: Status definitions
A6: Not Built | B6: Requirement has not yet been implemented.
A7: Ready to Test | B7: Implementation is available for acceptance testing.
A8: Pass | B8: Observed result meets the acceptance criterion.
A9: Fail | B9: Observed result does not meet the criterion.
A10: Blocked | B10: Testing cannot proceed because of an unresolved dependency or defect.
A11: Deferred | B11: Explicitly moved out of the current accepted scope/phase.
A12: N/A | B12: Not applicable to the tested build/platform.
A13: Pass with Known Issue | B13: Owner explicitly accepts a documented non-critical issue that does not affect security, data integrity, or core functionality.
A16: Acceptance authority | B16: The application owner provides final product/user acceptance. VS Code Copilot provides technical and automated validation.
A17: Security rule | B17: Security and data-integrity failures are release blockers and cannot be accepted as Pass with Known Issue.
A18: Production rule | B18: Production-changing database work requires explicit authorization for the exact migration. Routine development verification is separate.
A19: Import rule | B19: Recipe Import remains Decision Pending / Technical Investigation and does not block Phase 1.
... A22: Controlled update protocol | B22: Follow Acceptance Workbook Update Protocol.md. Modify this workbook in place and preserve formulas, validations, IDs, prior results, and owner notes.

Sheet Summary
A1: Meals Acceptance Summary
A3: Requirements baseline | B3: v0.3
A4: Total requirement IDs | B4: 216
A6: Worksheet | B6: Tests / Checks | C6: Pass | D6: Pass w/ Issue | E6: Fail | F6: Blocked | G6: Ready | H6: Not Built | I6: Deferred
A7: Functional Acceptance | B7: =MAX(0,COUNTA('Functional Acceptance'!B:B)-1) -> 173 | C7: =COUNTIF('Functional Acceptance'!$L:$L,"Pass") -> 7 | D7: =COUNTIF('Functional Acceptance'!$L:$L,"Pass with Known Issue") -> 0 | E7: =COUNTIF('Functional Acceptance'!$L:$L,"Fail") -> 0 | F7: =COUNTIF('Functional Acceptance'!$L:$L,"Blocked") -> 0 | G7: =COUNTIF('Functional Acceptance'!$L:$L,"Ready to Test") -> 0 | H7: =COUNTIF('Functional Acceptance'!$L:$L,"Not Built") -> 166 | I7: =COUNTIF('Functional Acceptance'!$L:$L,"Deferred") -> 0
A8: End-to-End Tests | B8: =MAX(0,COUNTA('End-to-End Tests'!B:B)-1) -> 12 | C8: =COUNTIF('End-to-End Tests'!$J:$J,"Pass") -> 1 | D8: =COUNTIF('End-to-End Tests'!$J:$J,"Pass with Known Issue") -> 0 | E8: =COUNTIF('End-to-End Tests'!$J:$J,"Fail") -> 0 | F8: =COUNTIF('End-to-End Tests'!$J:$J,"Blocked") -> 0 | G8: =COUNTIF('End-to-End Tests'!$J:$J,"Ready to Test") -> 0 | H8: =COUNTIF('End-to-End Tests'!$J:$J,"Not Built") -> 11 | I8: =COUNTIF('End-to-End Tests'!$J:$J,"Deferred") -> 0
A9: Security Acceptance | B9: =MAX(0,COUNTA('Security Acceptance'!B:B)-1) -> 22 | C9: =COUNTIF('Security Acceptance'!$N:$N,"Pass") -> 9 | D9: =COUNTIF('Security Acceptance'!$N:$N,"Pass with Known Issue") -> 0 | E9: =COUNTIF('Security Acceptance'!$N:$N,"Fail") -> 0 | F9: =COUNTIF('Security Acceptance'!$N:$N,"Blocked") -> 0 | G9: =COUNTIF('Security Acceptance'!$N:$N,"Ready to Test") -> 0 | H9: =COUNTIF('Security Acceptance'!$N:$N,"Not Built") -> 13 | I9: =COUNTIF('Security Acceptance'!$N:$N,"Deferred") -> 0
A10: Database Verification | B10: =MAX(0,COUNTA('Database Verification'!B:B)-1) -> 21 | C10: =COUNTIF('Database Verification'!$N:$N,"Pass") -> 15 | D10: =COUNTIF('Database Verification'!$N:$N,"Pass with Known Issue") -> 0 | E10: =COUNTIF('Database Verification'!$N:$N,"Fail") -> 0 | F10: =COUNTIF('Database Verification'!$N:$N,"Blocked") -> 0 | G10: =COUNTIF('Database Verification'!$N:$N,"Ready to Test") -> 0 | H10: =COUNTIF('Database Verification'!$N:$N,"Not Built") -> 6 | I10: =COUNTIF('Database Verification'!$N:$N,"Deferred") -> 0
A13: Phase | B13: Requirement count | C13: Notes
A14: 0 | B14: =SUMPRODUCT(((Coverage!$B$2:$B$223&"")=(A14&""))/COUNTIF(Coverage!$A$2:$A$223,Coverage!$A$2:$A$223)) -> 43 | C14: Foundation & Security
A15: 1 | B15: =SUMPRODUCT(((Coverage!$B$2:$B$223&"")=(A15&""))/COUNTIF(Coverage!$A$2:$A$223,Coverage!$A$2:$A$223)) -> 64 | C15: Recipe Core
A16: 2 | B16: =SUMPRODUCT(((Coverage!$B$2:$B$223&"")=(A16&""))/COUNTIF(Coverage!$A$2:$A$223,Coverage!$A$2:$A$223)) -> 52 | C16: Shopping
A17: 3 | B17: =SUMPRODUCT(((Coverage!$B$2:$B$223&"")=(A17&""))/COUNTIF(Coverage!$A$2:$A$223,Coverage!$A$2:$A$223)) -> 46 | C17: Planner Integration
A18: TBD | B18: =SUMPRODUCT(((Coverage!$B$2:$B$223&"")=(A18&""))/COUNTIF(Coverage!$A$2:$A$223,Coverage!$A$2:$A$223)) -> 11 | C18: Recipe Import investigation
A22: Phase | B22: Scope | C22: Requirement Count | D22: Required Tests | E22: Passed | F22: Pass w/ Issue | G22: Failed | H22: Blocked | I22: Deferred | J22: Technical Validation | K22: Functional Acceptance | L22: Security Acceptance | M22: Regression Scope | N22: Regression Acceptance | O22: Final Decision | P22: Accepted Date | Q22: Owner Notes
A23: 0 | B23: Foundation & Security | C23: =SUMPRODUCT(((Coverage!$B$2:$B$223&"")=(A23&""))/COUNTIF(Coverage!$A$2:$A$223,Coverage!$A$2:$A$223)) -> 43 | D23: Phase 0 technical/security/database + E2E-00 | E23: =COUNTIFS('Functional Acceptance'!D:D,A23,'Functional Acceptance'!L:L,"Pass")+COUNTIFS('Security Acceptance'!D:D,A23,'Security Acceptance'!N:N,"Pass")+COUNTIFS('Database Verification'!D:D,A23,'Database Verification'!N:N,"Pass")+COUNTIFS('End-to-End Tests'!C:C,A23,'End-to-End Tests'!J:J,"Pass") -> 32 | F23: =COUNTIFS('Functional Acceptance'!D:D,A23,'Functional Acceptance'!L:L,"Pass with Known Issue")+COUNTIFS('Security Acceptance'!D:D,A23,'Security Acceptance'!N:N,"Pass with Known Issue")+COUNTIFS('Database Verification'!D:D,A23,'Database Verification'!N:N,"Pass with Known Issue")+COUNTIFS('End-to-End Tests'!C:C,A23,'End-to-End Tests'!J:J,"Pass with Known Issue") -> 0 | G23: =COUNTIFS('Functional Acceptance'!D:D,A23,'Functional Acceptance'!L:L,"Fail")+COUNTIFS('Security Acceptance'!D:D,A23,'Security Acceptance'!N:N,"Fail")+COUNTIFS('Database Verification'!D:D,A23,'Database Verification'!N:N,"Fail")+COUNTIFS('End-to-End Tests'!C:C,A23,'End-to-End Tests'!J:J,"Fail") -> 0 | H23: =COUNTIFS('Functional Acceptance'!D:D,A23,'Functional Acceptance'!L:L,"Blocked")+COUNTIFS('Security Acceptance'!D:D,A23,'Security Acceptance'!N:N,"Blocked")+COUNTIFS('Database Verification'!D:D,A23,'Database Verification'!N:N,"Blocked")+COUNTIFS('End-to-End Tests'!C:C,A23,'End-to-End Tests'!J:J,"Blocked") -> 0 | I23: =COUNTIFS('Functional Acceptance'!D:D,A23,'Functional Acceptance'!L:L,"Deferred")+COUNTIFS('Security Acceptance'!D:D,A23,'Security Acceptance'!N:N,"Deferred")+COUNTIFS('Database Verification'!D:D,A23,'Database Verification'!N:N,"Deferred")+COUNTIFS('End-to-End Tests'!C:C,A23,'End-to-End Tests'!J:J,"Deferred") -> 0 | J23: Not Started | K23: Not Started | L23: Not Started | M23: Phase 0 auth/navigation after implementation | N23: Not Started | O23: Accepted | P23: 2026-10-28 | Q23: Phase 0A Meals foundation accepted. Live web routing, navigation, owner-auth integration, responsive shell, nested route refresh, and E2E-00 passed. Acceptance includes the Acceptance Workbook update tooling and Phase 0A release/deployment infrastructure. Recipe persistence, Recipe functionality beyond the Phase 0A shell/placeholders (including Add/Edit), Shopping functionality/persistence, meal-plan persistence, Weekly Planner meal integration, Recipe Import, future Meals database objects, and future Meals database-security/catalog verification remain outside this acceptance and are not yet accepted. Owner explicitly authorized this scope-limited acceptance on 2026-10-28 following P0-UAT-001.
A24: 1 | B24: Recipe Core | C24: =SUMPRODUCT(((Coverage!$B$2:$B$223&"")=(A24&""))/COUNTIF(Coverage!$A$2:$A$223,Coverage!$A$2:$A$223)) -> 64 | D24: Phase 1 Recipe tests + E2E-01,02,10 | E24: =COUNTIFS('Functional Acceptance'!D:D,A24,'Functional Acceptance'!L:L,"Pass")+COUNTIFS('Security Acceptance'!D:D,A24,'Security Acceptance'!N:N,"Pass")+COUNTIFS('Database Verification'!D:D,A24,'Database Verification'!N:N,"Pass")+COUNTIFS('End-to-End Tests'!C:C,A24,'End-to-End Tests'!J:J,"Pass") -> 0 | F24: =COUNTIFS('Functional Acceptance'!D:D,A24,'Functional Acceptance'!L:L,"Pass with Known Issue")+COUNTIFS('Security Acceptance'!D:D,A24,'Security Acceptance'!N:N,"Pass with Known Issue")+COUNTIFS('Database Verification'!D:D,A24,'Database Verification'!N:N,"Pass with Known Issue")+COUNTIFS('End-to-End Tests'!C:C,A24,'End-to-End Tests'!J:J,"Pass with Known Issue") -> 0 | G24: =COUNTIFS('Functional Acceptance'!D:D,A24,'Functional Acceptance'!L:L,"Fail")+COUNTIFS('Security Acceptance'!D:D,A24,'Security Acceptance'!N:N,"Fail")+COUNTIFS('Database Verification'!D:D,A24,'Database Verification'!N:N,"Fail")+COUNTIFS('End-to-End Tests'!C:C,A24,'End-to-End Tests'!J:J,"Fail") -> 0 | H24: =COUNTIFS('Functional Acceptance'!D:D,A24,'Functional Acceptance'!L:L,"Blocked")+COUNTIFS('Security Acceptance'!D:D,A24,'Security Acceptance'!N:N,"Blocked")+COUNTIFS('Database Verification'!D:D,A24,'Database Verification'!N:N,"Blocked")+COUNTIFS('End-to-End Tests'!C:C,A24,'End-to-End Tests'!J:J,"Blocked") -> 0 | I24: =COUNTIFS('Functional Acceptance'!D:D,A24,'Functional Acceptance'!L:L,"Deferred")+COUNTIFS('Security Acceptance'!D:D,A24,'Security Acceptance'!N:N,"Deferred")+COUNTIFS('Database Verification'!D:D,A24,'Database Verification'!N:N,"Deferred")+COUNTIFS('End-to-End Tests'!C:C,A24,'End-to-End Tests'!J:J,"Deferred") -> 0 | J24: Not Started | K24: Not Started | L24: Not Started | M24: Phase 0 authentication/navigation | N24: Not Started | O24: Not Started
A25: 2 | B25: Shopping | C25: =SUMPRODUCT(((Coverage!$B$2:$B$223&"")=(A25&""))/COUNTIF(Coverage!$A$2:$A$223,Coverage!$A$2:$A$223)) -> 52 | D25: Phase 2 Shopping tests + E2E-03,04,11 | E25: =COUNTIFS('Functional Acceptance'!D:D,A25,'Functional Acceptance'!L:L,"Pass")+COUNTIFS('Security Acceptance'!D:D,A25,'Security Acceptance'!N:N,"Pass")+COUNTIFS('Database Verification'!D:D,A25,'Database Verification'!N:N,"Pass")+COUNTIFS('End-to-End Tests'!C:C,A25,'End-to-End Tests'!J:J,"Pass") -> 0 | F25: =COUNTIFS('Functional Acceptance'!D:D,A25,'Functional Acceptance'!L:L,"Pass with Known Issue")+COUNTIFS('Security Acceptance'!D:D,A25,'Security Acceptance'!N:N,"Pass with Known Issue")+COUNTIFS('Database Verification'!D:D,A25,'Database Verification'!N:N,"Pass with Known Issue")+COUNTIFS('End-to-End Tests'!C:C,A25,'End-to-End Tests'!J:J,"Pass with Known Issue") -> 0 | G25: =COUNTIFS('Functional Acceptance'!D:D,A25,'Functional Acceptance'!L:L,"Fail")+COUNTIFS('Security Acceptance'!D:D,A25,'Security Acceptance'!N:N,"Fail")+COUNTIFS('Database Verification'!D:D,A25,'Database Verification'!N:N,"Fail")+COUNTIFS('End-to-End Tests'!C:C,A25,'End-to-End Tests'!J:J,"Fail") -> 0 | H25: =COUNTIFS('Functional Acceptance'!D:D,A25,'Functional Acceptance'!L:L,"Blocked")+COUNTIFS('Security Acceptance'!D:D,A25,'Security Acceptance'!N:N,"Blocked")+COUNTIFS('Database Verification'!D:D,A25,'Database Verification'!N:N,"Blocked")+COUNTIFS('End-to-End Tests'!C:C,A25,'End-to-End Tests'!J:J,"Blocked") -> 0 | I25: =COUNTIFS('Functional Acceptance'!D:D,A25,'Functional Acceptance'!L:L,"Deferred")+COUNTIFS('Security Acceptance'!D:D,A25,'Security Acceptance'!N:N,"Deferred")+COUNTIFS('Database Verification'!D:D,A25,'Database Verification'!N:N,"Deferred")+COUNTIFS('End-to-End Tests'!C:C,A25,'End-to-End Tests'!J:J,"Deferred") -> 0 | J25: Not Started | K25: Not Started | L25: Not Started | M25: Recipe create/search/detail/favorite | N25: Not Started | O25: Not Started
A26: 3 | B26: Planner Integration | C26: =SUMPRODUCT(((Coverage!$B$2:$B$223&"")=(A26&""))/COUNTIF(Coverage!$A$2:$A$223,Coverage!$A$2:$A$223)) -> 46 | D26: Phase 3 Planner tests + E2E-05 through 09 | E26: =COUNTIFS('Functional Acceptance'!D:D,A26,'Functional Acceptance'!L:L,"Pass")+COUNTIFS('Security Acceptance'!D:D,A26,'Security Acceptance'!N:N,"Pass")+COUNTIFS('Database Verification'!D:D,A26,'Database Verification'!N:N,"Pass")+COUNTIFS('End-to-End Tests'!C:C,A26,'End-to-End Tests'!J:J,"Pass") -> 0 | F26: =COUNTIFS('Functional Acceptance'!D:D,A26,'Functional Acceptance'!L:L,"Pass with Known Issue")+COUNTIFS('Security Acceptance'!D:D,A26,'Security Acceptance'!N:N,"Pass with Known Issue")+COUNTIFS('Database Verification'!D:D,A26,'Database Verification'!N:N,"Pass with Known Issue")+COUNTIFS('End-to-End Tests'!C:C,A26,'End-to-End Tests'!J:J,"Pass with Known Issue") -> 0 | G26: =COUNTIFS('Functional Acceptance'!D:D,A26,'Functional Acceptance'!L:L,"Fail")+COUNTIFS('Security Acceptance'!D:D,A26,'Security Acceptance'!N:N,"Fail")+COUNTIFS('Database Verification'!D:D,A26,'Database Verification'!N:N,"Fail")+COUNTIFS('End-to-End Tests'!C:C,A26,'End-to-End Tests'!J:J,"Fail") -> 0 | H26: =COUNTIFS('Functional Acceptance'!D:D,A26,'Functional Acceptance'!L:L,"Blocked")+COUNTIFS('Security Acceptance'!D:D,A26,'Security Acceptance'!N:N,"Blocked")+COUNTIFS('Database Verification'!D:D,A26,'Database Verification'!N:N,"Blocked")+COUNTIFS('End-to-End Tests'!C:C,A26,'End-to-End Tests'!J:J,"Blocked") -> 0 | I26: =COUNTIFS('Functional Acceptance'!D:D,A26,'Functional Acceptance'!L:L,"Deferred")+COUNTIFS('Security Acceptance'!D:D,A26,'Security Acceptance'!N:N,"Deferred")+COUNTIFS('Database Verification'!D:D,A26,'Database Verification'!N:N,"Deferred")+COUNTIFS('End-to-End Tests'!C:C,A26,'End-to-End Tests'!J:J,"Deferred") -> 0 | J26: Not Started | K26: Not Started | L26: Not Started | M26: Recipe core and Recipe-to-Shopping flow | N26: Not Started | O26: Not Started
A27: TBD | B27: Recipe Import | C27: =SUMPRODUCT(((Coverage!$B$2:$B$223&"")=(A27&""))/COUNTIF(Coverage!$A$2:$A$223,Coverage!$A$2:$A$223)) -> 11 | D27: Deferred | E27: =COUNTIFS('Functional Acceptance'!D:D,A27,'Functional Acceptance'!L:L,"Pass")+COUNTIFS('Security Acceptance'!D:D,A27,'Security Acceptance'!N:N,"Pass")+COUNTIFS('Database Verification'!D:D,A27,'Database Verification'!N:N,"Pass")+COUNTIFS('End-to-End Tests'!C:C,A27,'End-to-End Tests'!J:J,"Pass") -> 0 | F27: =COUNTIFS('Functional Acceptance'!D:D,A27,'Functional Acceptance'!L:L,"Pass with Known Issue")+COUNTIFS('Security Acceptance'!D:D,A27,'Security Acceptance'!N:N,"Pass with Known Issue")+COUNTIFS('Database Verification'!D:D,A27,'Database Verification'!N:N,"Pass with Known Issue")+COUNTIFS('End-to-End Tests'!C:C,A27,'End-to-End Tests'!J:J,"Pass with Known Issue") -> 0 | G27: =COUNTIFS('Functional Acceptance'!D:D,A27,'Functional Acceptance'!L:L,"Fail")+COUNTIFS('Security Acceptance'!D:D,A27,'Security Acceptance'!N:N,"Fail")+COUNTIFS('Database Verification'!D:D,A27,'Database Verification'!N:N,"Fail")+COUNTIFS('End-to-End Tests'!C:C,A27,'End-to-End Tests'!J:J,"Fail") -> 0 | H27: =COUNTIFS('Functional Acceptance'!D:D,A27,'Functional Acceptance'!L:L,"Blocked")+COUNTIFS('Security Acceptance'!D:D,A27,'Security Acceptance'!N:N,"Blocked")+COUNTIFS('Database Verification'!D:D,A27,'Database Verification'!N:N,"Blocked")+COUNTIFS('End-to-End Tests'!C:C,A27,'End-to-End Tests'!J:J,"Blocked") -> 0 | I27: =COUNTIFS('Functional Acceptance'!D:D,A27,'Functional Acceptance'!L:L,"Deferred")+COUNTIFS('Security Acceptance'!D:D,A27,'Security Acceptance'!N:N,"Deferred")+COUNTIFS('Database Verification'!D:D,A27,'Database Verification'!N:N,"Deferred")+COUNTIFS('End-to-End Tests'!C:C,A27,'End-to-End Tests'!J:J,"Deferred") -> 0 | J27: Not Started | K27: Not Started | L27: Not Started | M27: N/A | N27: Not Started | O27: Not Started

Sheet Functional Acceptance
A1: Test Run ID | B1: Test ID | C1: Requirement ID | D1: Phase | E1: Feature | F1: Type | G1: Platform | H1: Test Scenario | I1: Preconditions | J1: Test Steps | K1: Expected Result | L1: Status | M1: Tested Date | N1: Defect ID | O1: Evidence / Build Reference | P1: Defect / Notes
A2: P0-UAT-001 | B2: NAV-001-T01 | C2: NAV-001 | D2: 0 | E2: Navigation & Routing | F2: UI | G2: Both | H2: Verify: the main application navigation shall include a top-level item labeled Meals. | I2: Authenticated as the designated owner unless the requirement explicitly tests logged-out/non-owner behavior. | J2: 1. Arrange the stated preconditions. 2. Perform the behavior described by the requirement. 3. Observe persistence/navigation/state changes as applicable. 4. Compare the observed result with Expected Result. | K2: The main application navigation shall include a top-level item labeled Meals. | L2: Pass | M2: 46323 | N2: MEALS-DEF-001 | O2: spec/meals/README.md#phase-0a-technical-evidence; P0-UAT-001: designated owner reported live Life Manager UAT PASS on 2026-10-28; release 8298e2e0797ddff7d2d53cc058fa41fb407ac0ab; recorded by Copilot from owner report, not automated authenticated verification | P2: Top-level Meals link technically validated; owner UAT remains. MEALS-DEF-001 CLOSED: initial workbook date marshaling failed before save; original bytes preserved. COM variant setter fixed and isolated-copy dated-update/integrity tests passed. Local dev base 07fee6170fd48880d4bde57e13d05e65c3cbbc0c.; P0-UAT-001 owner report: Meals appeared in live navigation; navigation/routing, desktop and mobile responsive presentation, and complete E2E-00 passed; everything else worked as expected. Add Recipe is intentionally nonfunctional in Phase 0A; Recipe Editor is Phase 1, not a defect or future-feature acceptance. Prior technical run P0-TECH-001 and its evidence remain above. Mobile result is live-web UAT, not a native Capacitor release.
A3: P0-UAT-001 | B3: NAV-002-T01 | C3: NAV-002 | D3: 0 | E3: Navigation & Routing | F3: UI | G3: Both | H3: Verify: within Meals, the primary feature navigation shall expose Recipes and Shopping. | I3: Authenticated as the designated owner unless the requirement explicitly tests logged-out/non-owner behavior. | J3: 1. Arrange the stated preconditions. 2. Perform the behavior described by the requirement. 3. Observe persistence/navigation/state changes as applicable. 4. Compare the observed result with Expected Result. | K3: Within Meals, the primary feature navigation shall expose Recipes and Shopping. | L3: Pass | M3: 46323 | O3: spec/meals/README.md#phase-0a-technical-evidence; P0-UAT-001: designated owner reported live Life Manager UAT PASS on 2026-10-28; release 8298e2e0797ddff7d2d53cc058fa41fb407ac0ab; recorded by Copilot from owner report, not automated authenticated verification | P3: Recipes/Shopping switching and active states technically verified. Non-data-backed Phase 0A placeholders only; owner UAT remains.; P0-UAT-001 owner report: Meals appeared in live navigation; navigation/routing, desktop and mobile responsive presentation, and complete E2E-00 passed; everything else worked as expected. Add Recipe is intentionally nonfunctional in Phase 0A; Recipe Editor is Phase 1, not a defect or future-feature acceptance. Prior technical run P0-TECH-001 and its evidence remain above. Mobile result is live-web UAT, not a native Capacitor release.
A4: P0-UAT-001 | B4: NAV-003-T01 | C4: NAV-003 | D4: 0 | E4: Navigation & Routing | F4: FUNC | G4: Both | H4: Verify: meals routes shall use the /meals namespace rather than /cooking. | I4: Authenticated as the designated owner unless the requirement explicitly tests logged-out/non-owner behavior. | J4: 1. Arrange the stated preconditions. 2. Perform the behavior described by the requirement. 3. Observe persistence/navigation/state changes as applicable. 4. Compare the observed result with Expected Result. | K4: Meals routes shall use the /meals namespace rather than /cooking. | L4: Pass | M4: 46323 | O4: spec/meals/README.md#phase-0a-technical-evidence; P0-UAT-001: designated owner reported live Life Manager UAT PASS on 2026-10-28; release 8298e2e0797ddff7d2d53cc058fa41fb407ac0ab; recorded by Copilot from owner report, not automated authenticated verification | P4: Explicit /meals namespace and unknown/nested Meals isolation tested; /cooking not introduced. Owner UAT remains.; P0-UAT-001 owner report: Meals appeared in live navigation; navigation/routing, desktop and mobile responsive presentation, and complete E2E-00 passed; everything else worked as expected. Add Recipe is intentionally nonfunctional in Phase 0A; Recipe Editor is Phase 1, not a defect or future-feature acceptance. Prior technical run P0-TECH-001 and its evidence remain above. Mobile result is live-web UAT, not a native Capacitor release.
A5: P0-UAT-001 | B5: NAV-004-T01 | C5: NAV-004 | D5: 0 | E5: Navigation & Routing | F5: FUNC | G5: Both | H5: Verify: the Recipe Library route shall be /meals/recipes. | I5: Authenticated as the designated owner unless the requirement explicitly tests logged-out/non-owner behavior. | J5: 1. Arrange the stated preconditions. 2. Perform the behavior described by the requirement. 3. Observe persistence/navigation/state changes as applicable. 4. Compare the observed result with Expected Result. | K5: The Recipe Library route shall be /meals/recipes. | L5: Pass | M5: 46323 | O5: spec/meals/README.md#phase-0a-technical-evidence; P0-UAT-001: designated owner reported live Life Manager UAT PASS on 2026-10-28; release 8298e2e0797ddff7d2d53cc058fa41fb407ac0ab; recorded by Copilot from owner report, not automated authenticated verification | P5: /meals/recipes foundation route tested beneath actual hosted basename; no Recipe Library data functionality claimed. Owner UAT remains.; P0-UAT-001 owner report: Meals appeared in live navigation; navigation/routing, desktop and mobile responsive presentation, and complete E2E-00 passed; everything else worked as expected. Add Recipe is intentionally nonfunctional in Phase 0A; Recipe Editor is Phase 1, not a defect or future-feature acceptance. Prior technical run P0-TECH-001 and its evidence remain above. Mobile result is live-web UAT, not a native Capacitor release.
B6: NAV-005-T01 | C6: NAV-005 | D6: 1 | E6: Navigation & Routing | F6: FUNC | G6: Both | H6: Verify: the manual Add Recipe route shall be /meals/recipes/new. | I6: Authenticated as the designated owner unless the requirement explicitly tests logged-out/non-owner behavior. | J6: 1. Arrange the stated preconditions. 2. Perform the behavior described by the requirement. 3. Observe persistence/navigation/state changes as applicable. 4. Compare the observed result with Expected Result. | K6: The manual Add Recipe route shall be /meals/recipes/new. | L6: Not Built
B7: NAV-006-T01 | C7: NAV-006 | D7: 1 | E7: Navigation & Routing | F7: FUNC | G7: Both | H7: Verify: recipe Detail shall use a route equivalent to /meals/recipes/:id. | I7: Authenticated as the designated owner unless the requirement explicitly tests logged-out/non-owner behavior. | J7: 1. Arrange the stated preconditions. 2. Perform the behavior described by the requirement. 3. Observe persistence/navigation/state changes as applicable. 4. Compare the observed result with Expected Result. | K7: Recipe Detail shall use a route equivalent to /meals/recipes/:id. | L7: Not Built
B8: NAV-007-T01 | C8: NAV-007 | D8: 2 | E8: Navigation & Routing | F8: FUNC | G8: Both | H8: Verify: shopping shall use /meals/shopping. | I8: Authenticated as the designated owner unless the requirement explicitly tests logged-out/non-owner behavior. | J8: 1. Arrange the stated preconditions. 2. Perform the behavior described by the requirement. 3. Observe persistence/navigation/state changes as applicable. 4. Compare the observed result with Expected Result. | K8: Shopping shall use /meals/shopping. | L8: Not Built
A9: P0-UAT-001 | B9: NAV-009-T01 | C9: NAV-009 | D9: 0 | E9: Navigation & Routing | F9: FUNC | G9: Both | H9: Verify: navigating to /meals shall redirect to /meals/recipes. | I9: Authenticated as the designated owner unless the requirement explicitly tests logged-out/non-owner behavior. | J9: 1. Arrange the stated preconditions. 2. Perform the behavior described by the requirement. 3. Observe persistence/navigation/state changes as applicable. 4. Compare the observed result with Expected Result. | K9: Navigating to /meals shall redirect to /meals/recipes. | L9: Pass | M9: 46323 | O9: spec/meals/README.md#phase-0a-technical-evidence; P0-UAT-001: designated owner reported live Life Manager UAT PASS on 2026-10-28; release 8298e2e0797ddff7d2d53cc058fa41fb407ac0ab; recorded by Copilot from owner report, not automated authenticated verification | P9: /meals replacement redirect to /meals/recipes verified in local browser with the real router and synthetic Auth transport. Owner UAT remains.; P0-UAT-001 owner report: Meals appeared in live navigation; navigation/routing, desktop and mobile responsive presentation, and complete E2E-00 passed; everything else worked as expected. Add Recipe is intentionally nonfunctional in Phase 0A; Recipe Editor is Phase 1, not a defect or future-feature acceptance. Prior technical run P0-TECH-001 and its evidence remain above. Mobile result is live-web UAT, not a native Capacitor release.
B10: RL-UI-001-T01-D | C10: RL-UI-001 | D10: 1 | E10: Recipe Library | F10: UI | G10: Desktop | H10: Verify: the Recipe Library shall be text-oriented and shall not display recipe thumbnails. | I10: Authenticated as the designated owner; required baseline Meals data exists unless the test is specifically for an empty state. | J10: 1. Open the applicable feature at a supported desktop width. 2. Perform the behavior described by the requirement. 3. Compare the observed result with Expected Result. | K10: The Recipe Library shall be text-oriented and shall not display recipe thumbnails. | L10: Not Built
B11: RL-UI-001-T01-M | C11: RL-UI-001 | D11: 1 | E11: Recipe Library | F11: UI | G11: Mobile | H11: Verify: the Recipe Library shall be text-oriented and shall not display recipe thumbnails. | I11: Authenticated as the designated owner; required baseline Meals data exists unless the test is specifically for an empty state. | J11: 1. Open the applicable feature at a supported mobile/Capacitor width. 2. Perform the behavior described by the requirement using touch-sized controls. 3. Compare the observed result with Expected Result. | K11: The Recipe Library shall be text-oriented and shall not display recipe thumbnails. | L11: Not Built
B12: RL-UI-002-T01 | C12: RL-UI-002 | D12: 1 | E12: Recipe Library | F12: UI | G12: Desktop | H12: Verify: desktop shall display compact recipe rows with selection, Favorite, Name, Category, Cuisine, and Source. | I12: Authenticated as the designated owner; required baseline Meals data exists unless the test is specifically for an empty state. | J12: 1. Open the applicable feature at a supported desktop width. 2. Perform the behavior described by the requirement. 3. Compare the observed result with Expected Result. | K12: Desktop shall display compact recipe rows with selection, Favorite, Name, Category, Cuisine, and Source. | L12: Not Built
B13: RL-UI-003-T01 | C13: RL-UI-003 | D13: 1 | E13: Recipe Library | F13: UI | G13: Mobile | H13: Verify: mobile shall display compact recipe rows with a Favorite control and concise classification information without a desktop-style data table. | I13: Authenticated as the designated owner; required baseline Meals data exists unless the test is specifically for an empty state. | J13: 1. Open the applicable feature at a supported mobile/Capacitor width. 2. Perform the behavior described by the requirement using touch-sized controls. 3. Compare the observed result with Expected Result. | K13: Mobile shall display compact recipe rows with a Favorite control and concise classification information without a desktop-style data table. | L13: Not Built
B14: RL-FUNC-001-T01 | C14: RL-FUNC-001 | D14: 1 | E14: Recipe Library | F14: FUNC | G14: Both | H14: Verify: the Recipe Library shall provide a prominently available text search box. | I14: Authenticated as the designated owner; required baseline Meals data exists unless the test is specifically for an empty state. | J14: 1. Arrange the stated preconditions. 2. Perform the behavior described by the requirement. 3. Observe persistence/navigation/state changes as applicable. 4. Compare the observed result with Expected Result. | K14: The Recipe Library shall provide a prominently available text search box. | L14: Not Built
B15: RL-FUNC-002-T01 | C15: RL-FUNC-002 | D15: 1 | E15: Recipe Library | F15: FUNC | G15: Both | H15: Verify: recipe title search shall use case-insensitive substring matching. | I15: Authenticated as the designated owner; required baseline Meals data exists unless the test is specifically for an empty state. | J15: 1. Create Recipes whose titles include mixed-case target text and near-matches. 2. Search using a lowercase substring. 3. Repeat using uppercase/mixed case. 4. Confirm every and only title substring match is returned. | K15: Recipe title search shall use case-insensitive substring matching. | L15: Not Built
B16: RL-FUNC-003-T01 | C16: RL-FUNC-003 | D16: 1 | E16: Recipe Library | F16: FUNC | G16: Both | H16: Verify: ingredient search shall use case-insensitive substring matching against stored ingredient text. | I16: Authenticated as the designated owner; required baseline Meals data exists unless the test is specifically for an empty state. | J16: 1. Create Recipes with a distinctive ingredient line not present in their titles. 2. Search using a substring from that ingredient in different letter case. 3. Confirm matching Recipes are returned and unrelated Recipes are not. | K16: Ingredient search shall use case-insensitive substring matching against stored ingredient text. | L16: Not Built
B17: RL-FUNC-004-T01 | C17: RL-FUNC-004 | D17: 1 | E17: Recipe Library | F17: FUNC | G17: Both | H17: Verify: the Recipe Library shall filter by Category. | I17: Authenticated as the designated owner; required baseline Meals data exists unless the test is specifically for an empty state. | J17: 1. Arrange the stated preconditions. 2. Perform the behavior described by the requirement. 3. Observe persistence/navigation/state changes as applicable. 4. Compare the observed result with Expected Result. | K17: The Recipe Library shall filter by Category. | L17: Not Built
B18: RL-FUNC-005-T01 | C18: RL-FUNC-005 | D18: 1 | E18: Recipe Library | F18: FUNC | G18: Both | H18: Verify: the Recipe Library shall filter by Cuisine. | I18: Authenticated as the designated owner; required baseline Meals data exists unless the test is specifically for an empty state. | J18: 1. Arrange the stated preconditions. 2. Perform the behavior described by the requirement. 3. Observe persistence/navigation/state changes as applicable. 4. Compare the observed result with Expected Result. | K18: The Recipe Library shall filter by Cuisine. | L18: Not Built
B19: RL-FUNC-006-T01 | C19: RL-FUNC-006 | D19: 1 | E19: Recipe Library | F19: FUNC | G19: Both | H19: Verify: the Recipe Library shall filter to Favorites. | I19: Authenticated as the designated owner; required baseline Meals data exists unless the test is specifically for an empty state. | J19: 1. Arrange the stated preconditions. 2. Perform the behavior described by the requirement. 3. Observe persistence/navigation/state changes as applicable. 4. Compare the observed result with Expected Result. | K19: The Recipe Library shall filter to Favorites. | L19: Not Built
B20: RL-FUNC-007-T01 | C20: RL-FUNC-007 | D20: 1 | E20: Recipe Library | F20: FUNC | G20: Desktop | H20: Verify: desktop Name, Category, Cuisine, and Source columns shall support ascending/descending sorting from their column headers. | I20: Authenticated as the designated owner; required baseline Meals data exists unless the test is specifically for an empty state. | J20: 1. Open the applicable feature at a supported desktop width. 2. Perform the behavior described by the requirement. 3. Compare the observed result with Expected Result. | K20: Desktop Name, Category, Cuisine, and Source columns shall support ascending/descending sorting from their column headers. | L20: Not Built
B21: RL-FUNC-008-T01 | C21: RL-FUNC-008 | D21: 1 | E21: Recipe Library | F21: FUNC | G21: Mobile | H21: Verify: mobile shall not display a separate A-Z sort control. | I21: Authenticated as the designated owner; required baseline Meals data exists unless the test is specifically for an empty state. | J21: 1. Open the applicable feature at a supported mobile/Capacitor width. 2. Perform the behavior described by the requirement using touch-sized controls. 3. Compare the observed result with Expected Result. | K21: Mobile shall not display a separate A-Z sort control. | L21: Not Built
... B162: PM-FUNC-012-T01 | C162: PM-FUNC-012 | D162: 3 | E162: Planner Meal Management | F162: FUNC | G162: Both | H162: Verify: a meal-plan mutation failure shall not be presented as successful; existing persisted meal content shall remain available and the user shall be able to retry where appropriate. | I162: Authenticated as the designated owner; required baseline Meals data exists unless the test is specifically for an empty state. | J162: 1. Arrange the stated preconditions. 2. Perform the behavior described by the requirement. 3. Observe persistence/navigation/state changes as applicable. 4. Compare the observed result with Expected Result. | K162: A meal-plan mutation failure shall not be presented as successful; existing persisted meal content shall remain available and the user shall be able to retry where appropriate. | L162: Not Built
A163: P0-UAT-001 | B163: RESP-001-T01-D | C163: RESP-001 | D163: 0 | E163: Responsive | F163: RESP | G163: Desktop | H163: Verify: meals shall use one responsive React implementation for web and Capacitor rather than separate desktop/mobile applications. | I163: Authenticated as the designated owner; required baseline Meals data exists unless the test is specifically for an empty state. | J163: 1. Open the applicable feature at a supported desktop width. 2. Perform the behavior described by the requirement. 3. Compare the observed result with Expected Result. | K163: Meals shall use one responsive React implementation for web and Capacitor rather than separate desktop/mobile applications. | L163: Pass | M163: 46323 | O163: spec/meals/README.md#phase-0a-technical-evidence; P0-UAT-001: designated owner reported live Life Manager UAT PASS on 2026-10-28; release 8298e2e0797ddff7d2d53cc058fa41fb407ac0ab; recorded by Copilot from owner report, not automated authenticated verification | P163: Shared shell at 1280px: no horizontal overflow, correct active links, 44px internal navigation. Desktop screenshot inspected; owner visual/usability UAT remains.; P0-UAT-001 owner report: Meals appeared in live navigation; navigation/routing, desktop and mobile responsive presentation, and complete E2E-00 passed; everything else worked as expected. Add Recipe is intentionally nonfunctional in Phase 0A; Recipe Editor is Phase 1, not a defect or future-feature acceptance. Prior technical run P0-TECH-001 and its evidence remain above. Mobile result is live-web UAT, not a native Capacitor release.
A164: P0-UAT-001 | B164: RESP-001-T01-M | C164: RESP-001 | D164: 0 | E164: Responsive | F164: RESP | G164: Mobile | H164: Verify: meals shall use one responsive React implementation for web and Capacitor rather than separate desktop/mobile applications. | I164: Authenticated as the designated owner; required baseline Meals data exists unless the test is specifically for an empty state. | J164: 1. Open the applicable feature at a supported mobile/Capacitor width. 2. Perform the behavior described by the requirement using touch-sized controls. 3. Compare the observed result with Expected Result. | K164: Meals shall use one responsive React implementation for web and Capacitor rather than separate desktop/mobile applications. | L164: Pass | M164: 46323 | O164: spec/meals/README.md#phase-0a-technical-evidence; P0-UAT-001: designated owner reported live Life Manager UAT PASS on 2026-10-28; release 8298e2e0797ddff7d2d53cc058fa41fb407ac0ab; recorded by Copilot from owner report, not automated authenticated verification | P164: Same responsive shell at 375px: no horizontal overflow, wrapped navigation, 44px internal controls. Mobile browser screenshot inspected; physical Capacitor/device UAT remains.; P0-UAT-001 owner report: Meals appeared in live navigation; navigation/routing, desktop and mobile responsive presentation, and complete E2E-00 passed; everything else worked as expected. Add Recipe is intentionally nonfunctional in Phase 0A; Recipe Editor is Phase 1, not a defect or future-feature acceptance. Prior technical run P0-TECH-001 and its evidence remain above. Mobile result is live-web UAT, not a native Capacitor release.
B165: RESP-002-T01 | C165: RESP-002 | D165: 1 | E165: Responsive | F165: RESP | G165: Desktop | H165: Verify: desktop Meals surfaces shall prioritize compact data density and efficient management. | I165: Authenticated as the designated owner; required baseline Meals data exists unless the test is specifically for an empty state. | J165: 1. Open the applicable feature at a supported desktop width. 2. Perform the behavior described by the requirement. 3. Compare the observed result with Expected Result. | K165: Desktop Meals surfaces shall prioritize compact data density and efficient management. | L165: Not Built
B166: RESP-003-T01 | C166: RESP-003 | D166: 1 | E166: Responsive | F166: RESP | G166: Mobile | H166: Verify: mobile Meals surfaces shall prioritize minimal presentation, touch-friendly controls, and the current task. | I166: Authenticated as the designated owner; required baseline Meals data exists unless the test is specifically for an empty state. | J166: 1. Open the applicable feature at a supported mobile/Capacitor width. 2. Perform the behavior described by the requirement using touch-sized controls. 3. Compare the observed result with Expected Result. | K166: Mobile Meals surfaces shall prioritize minimal presentation, touch-friendly controls, and the current task. | L166: Not Built
B167: STATE-001-T01 | C167: STATE-001 | D167: 1 | E167: Cross-cutting States | F167: STATE | G167: Both | H167: Verify: data-backed Meals pages shall expose an appropriate loading state consistent with existing HomeMaintenanceApp patterns and shall not display a misleading empty state while initial data is pending. Exact spinner/skeleton/text treatment is an implementation detail. | I167: Authenticated as the designated owner unless the requirement explicitly tests logged-out/non-owner behavior. | J167: 1. Arrange the stated preconditions. 2. Perform the behavior described by the requirement. 3. Observe persistence/navigation/state changes as applicable. 4. Compare the observed result with Expected Result. | K167: Data-backed Meals pages shall expose an appropriate loading state consistent with existing HomeMaintenanceApp patterns and shall not display a misleading empty state while initial data is pending. Exact spinner/skeleton/text treatment is an implementation detail. | L167: Not Built
B168: STATE-002-T01 | C168: STATE-002 | D168: 1 | E168: Cross-cutting States | F168: STATE | G168: Both | H168: Verify: data-backed Meals pages shall expose an actionable error state when required data cannot be loaded. | I168: Authenticated as the designated owner unless the requirement explicitly tests logged-out/non-owner behavior. | J168: 1. Arrange the stated preconditions. 2. Perform the behavior described by the requirement. 3. Observe persistence/navigation/state changes as applicable. 4. Compare the observed result with Expected Result. | K168: Data-backed Meals pages shall expose an actionable error state when required data cannot be loaded. | L168: Not Built
B169: STATE-003-T01 | C169: STATE-003 | D169: 1 | E169: Cross-cutting States | F169: STATE | G169: Both | H169: Verify: save/mutation interactions shall prevent accidental duplicate submission while a save is in progress. | I169: Authenticated as the designated owner unless the requirement explicitly tests logged-out/non-owner behavior. | J169: 1. Arrange the stated preconditions. 2. Perform the behavior described by the requirement. 3. Observe persistence/navigation/state changes as applicable. 4. Compare the observed result with Expected Result. | K169: Save/mutation interactions shall prevent accidental duplicate submission while a save is in progress. | L169: Not Built
B170: STATE-004-T01-D | C170: STATE-004 | D170: 1 | E170: Cross-cutting States | F170: STATE | G170: Desktop | H170: Verify: true empty states shall be distinguished from zero-match search/filter states and shall expose recovery actions appropriate to the condition. | I170: Authenticated as the designated owner unless the requirement explicitly tests logged-out/non-owner behavior. | J170: 1. Open the applicable feature at a supported desktop width. 2. Perform the behavior described by the requirement. 3. Compare the observed result with Expected Result. | K170: True empty states shall be distinguished from zero-match search/filter states and shall expose recovery actions appropriate to the condition. | L170: Not Built
B171: STATE-004-T01-M | C171: STATE-004 | D171: 1 | E171: Cross-cutting States | F171: STATE | G171: Mobile | H171: Verify: true empty states shall be distinguished from zero-match search/filter states and shall expose recovery actions appropriate to the condition. | I171: Authenticated as the designated owner unless the requirement explicitly tests logged-out/non-owner behavior. | J171: 1. Open the applicable feature at a supported mobile/Capacitor width. 2. Perform the behavior described by the requirement using touch-sized controls. 3. Compare the observed result with Expected Result. | K171: True empty states shall be distinguished from zero-match search/filter states and shall expose recovery actions appropriate to the condition. | L171: Not Built
B172: STATE-005-T01 | C172: STATE-005 | D172: 1 | E172: Cross-cutting States | F172: STATE | G172: Both | H172: Verify: destructive Recipe deletion shall require explicit confirmation. | I172: Authenticated as the designated owner unless the requirement explicitly tests logged-out/non-owner behavior. | J172: 1. Arrange the stated preconditions. 2. Perform the behavior described by the requirement. 3. Observe persistence/navigation/state changes as applicable. 4. Compare the observed result with Expected Result. | K172: Destructive Recipe deletion shall require explicit confirmation. | L172: Not Built
B173: STATE-006-T01 | C173: STATE-006 | D173: 2 | E173: Cross-cutting States | F173: STATE | G173: Both | H173: Verify: clear List shall use the Shopping-specific confirmation defined in SHOP-FUNC-012; Clear Checked and Planner meal occurrence removal shall remain confirmation-free. | I173: Authenticated as the designated owner unless the requirement explicitly tests logged-out/non-owner behavior. | J173: 1. Arrange the stated preconditions. 2. Perform the behavior described by the requirement. 3. Observe persistence/navigation/state changes as applicable. 4. Compare the observed result with Expected Result. | K173: Clear List shall use the Shopping-specific confirmation defined in SHOP-FUNC-012; Clear Checked and Planner meal occurrence removal shall remain confirmation-free. | L173: Not Built
B174: STATE-007-T01 | C174: STATE-007 | D174: 1 | E174: Cross-cutting States | F174: STATE | G174: Both | H174: Verify: mutation failures shall clearly indicate that the attempted change did not persist and shall preserve user-entered or currently persisted content where practical so the action can be retried. | I174: Authenticated as the designated owner unless the requirement explicitly tests logged-out/non-owner behavior. | J174: 1. Arrange the stated preconditions. 2. Perform the behavior described by the requirement. 3. Observe persistence/navigation/state changes as applicable. 4. Compare the observed result with Expected Result. | K174: Mutation failures shall clearly indicate that the attempted change did not persist and shall preserve user-entered or currently persisted content where practical so the action can be retried. | L174: Not Built

Sheet Security Acceptance
A1: Test Run ID | B1: Test ID | C1: Requirement ID | D1: Phase | E1: Feature | F1: Type | G1: Platform | H1: Execution Owner | I1: Environment | J1: Test Scenario | K1: Preconditions | L1: Test Steps | M1: Expected Result | N1: Status | O1: Tested Date | P1: Defect ID | Q1: Evidence / Build Reference | R1: Defect / Notes
A2: P0-TECH-001 | B2: ARCH-001-T01 | C2: ARCH-001 | D2: 0 | E2: Architecture & Security | F2: ARCH | G2: Both | H2: COPILOT | I2: Local/Test | J2: Verify: meals shall use the existing application Supabase Auth session and shall not introduce a separate Meals authentication concept. | K2: Use the identity/environment required by the test; production-changing actions require separate authorization. | L2: 1. Arrange the preconditions. 2. Perform the user/database action described by the requirement. 3. Observe the result. 4. Compare the observed result with Expected Result. | M2: Meals shall use the existing application Supabase Auth session and shall not introduce a separate Meals authentication concept. | N2: Pass | O2: 46323 | Q2: spec/meals/README.md#phase-0a-technical-evidence; web release validation: spec/meals/README.md#web-release-validation | R2: Executed routing/auth regressions and local browser synthetic-transport checks. Meals mounts under the unchanged existing exact-owner boundary/controller; no separate Meals login or data subsystem.
B3: ARCH-002-T01 | C3: ARCH-002 | D3: 0 | E3: Architecture & Security | F3: ARCH | G3: Both | H3: COPILOT | I3: Local/Test | J3: Verify: meals shall not weaken, bypass, or replace the existing exact-owner RLS authorization model. | K3: Use the identity/environment required by the test; production-changing actions require separate authorization. | L3: 1. Verify the behavior through the application using the specified identity. 2. Independently attempt the corresponding Supabase data/API operation using the same authorization context. 3. Confirm both layers produce the expected allow/deny result. 4. Capture evidence. | M3: Meals shall not weaken, bypass, or replace the existing exact-owner RLS authorization model. | N3: Not Built
A4: P0B-DB-001 | B4: ARCH-003-T01 | C4: ARCH-003 | D4: 0 | E4: Architecture & Security | F4: ARCH | G4: Both | H4: COPILOT | I4: Production Read-Only | J4: Verify: the designated human owner UUID for production authorization is e72bccd9-ec2b-4822-bb5c-b7c1f39dcf60. | K4: Use the identity/environment required by the test; production-changing actions require separate authorization. | L4: 1. Arrange the preconditions. 2. Perform the user/database action described by the requirement. 3. Observe the result. 4. Compare the observed result with Expected Result. | M4: The designated human owner UUID for production authorization is e72bccd9-ec2b-4822-bb5c-b7c1f39dcf60. | N4: Pass | O4: 2026-10-28 | Q4: P0B-DB-001; package 0d30359ab5cdd4aa3577c33823de1bbc80a3d4f2; spec/meals/Phase 0B Recipe Persistence Design.md section 28; meals-db-final-manifest.json SHA256 4cbbc3eac24c13860d39ee3a0d8c6ae79c638cc5967d5274d1e7ea219091f8da; complete evidence in session b7458d86-6190-4718-8779-7c2b79a30630/files | R4: P0B-DB-001 Recipe foundation scope only. Captured production catalog and synthetic SQL SET ROLE/claim evidence, not live JWT/API authentication, owner application UAT or Recipe UI evidence. Future Meals objects require their own verification. No deployment blocker observed; blocker classification field is unchanged. Reversal prepared, not executed; test-only transaction rollback is not migration reversal. Owner identity confirmed by preflight and exact UUID in all 12 deployed policies.
B5: ARCH-004-T01 | C5: ARCH-004 | D5: 0 | E5: Architecture & Security | F5: ARCH | G5: Both | H5: COPILOT | I5: Local/Test | J5: Verify: logged-out/anonymous clients shall receive no access to private Meals application data or private Meals RPCs. | K5: Use the identity/environment required by the test; production-changing actions require separate authorization. | L5: 1. Verify the behavior through the application using the specified identity. 2. Independently attempt the corresponding Supabase data/API operation using the same authorization context. 3. Confirm both layers produce the expected allow/deny result. 4. Capture evidence. | M5: Logged-out/anonymous clients shall receive no access to private Meals application data or private Meals RPCs. | N5: Not Built
B6: ARCH-005-T01 | C6: ARCH-005 | D6: 0 | E6: Architecture & Security | F6: ARCH | G6: Both | H6: COPILOT | I6: Local/Test | J6: Verify: an authenticated identity other than the designated owner shall receive no access to owner Meals data. | K6: Use the identity/environment required by the test; production-changing actions require separate authorization. | L6: 1. Verify the behavior through the application using the specified identity. 2. Independently attempt the corresponding Supabase data/API operation using the same authorization context. 3. Confirm both layers produce the expected allow/deny result. 4. Capture evidence. | M6: An authenticated identity other than the designated owner shall receive no access to owner Meals data. | N6: Not Built
A7: P0-TECH-001 | B7: ARCH-006-T01 | C7: ARCH-006 | D7: 0 | E7: Architecture & Security | F7: ARCH | G7: Both | H7: COPILOT | I7: Source/Build Inspection | J7: Verify: service_role credentials shall never be exposed to browser code. | K7: Use the identity/environment required by the test; production-changing actions require separate authorization. | L7: 1. Arrange the preconditions. 2. Perform the user/database action described by the requirement. 3. Observe the result. 4. Compare the observed result with Expected Result. | M7: service_role credentials shall never be exposed to browser code. | N7: Pass | O7: 46323 | Q7: spec/meals/README.md#phase-0a-technical-evidence; web release validation: spec/meals/README.md#web-release-validation | R7: Executed browser source/production-build inspection: no service-role JWT, privileged secret-key literal or private-key material exposed by Meals. Normal production build excludes synthetic Auth fixture.
A8: P0-TECH-001 | B8: ARCH-007-T01 | C8: ARCH-007 | D8: 0 | E8: Architecture & Security | F8: ARCH | G8: Both | H8: COPILOT | I8: Local/Test | J8: Verify: meals shall not depend on planner_curated_api, planner_broker_access_token_hook, the abandoned broker Auth identity, broker column grants, or the old Custom Access Token Hook architecture. | K8: Use the identity/environment required by the test; production-changing actions require separate authorization. | L8: 1. Arrange the preconditions. 2. Perform the user/database action described by the requirement. 3. Observe the result. 4. Compare the observed result with Expected Result. | M8: Meals shall not depend on planner_curated_api, planner_broker_access_token_hook, the abandoned broker Auth identity, broker column grants, or the old Custom Access Token Hook architecture. | N8: Pass | O8: 46323 | Q8: spec/meals/README.md#phase-0a-technical-evidence; web release validation: spec/meals/README.md#web-release-validation | R8: Executed source/build inspection: no broker role, hook, abandoned identity or broker dependency in Meals. No Meals database objects exist in this slice; no catalog/security grant claim for future objects.
A9: P0-TECH-001 | B9: ARCH-008-T01 | C9: ARCH-008 | D9: 0 | E9: Architecture & Security | F9: ARCH | G9: Both | H9: COPILOT | I9: Local/Test | J9: Verify: meals implementation shall not be blocked by the separate broker cleanup workstream or the Supabase Support inquiry about managed supabase_admin default privileges. | K9: Use the identity/environment required by the test; production-changing actions require separate authorization. | L9: 1. Arrange the preconditions. 2. Perform the user/database action described by the requirement. 3. Observe the result. 4. Compare the observed result with Expected Result. | M9: Meals implementation shall not be blocked by the separate broker cleanup workstream or the Supabase Support inquiry about managed supabase_admin default privileges. | N9: Pass | O9: 46323 | Q9: spec/meals/README.md#phase-0a-technical-evidence; web release validation: spec/meals/README.md#web-release-validation | R9: Foundation built/tested without broker cleanup or managed-default remediation. Broker artifacts and production configuration unchanged.
A10: P0B-DB-001 | B10: ARCH-009-T01 | C10: ARCH-009 | D10: 0 | E10: Architecture & Security | F10: ARCH | G10: Both | H10: COPILOT | I10: Production Read-Only | J10: Verify: meals security shall not rely on inherited/default PostgreSQL or Supabase privileges; each new object shall be explicitly secured and verified. | K10: Use the identity/environment required by the test; production-changing actions require separate authorization. | L10: 1. Arrange the preconditions. 2. Perform the user/database action described by the requirement. 3. Observe the result. 4. Compare the observed result with Expected Result. | M10: Meals security shall not rely on inherited/default PostgreSQL or Supabase privileges; each new object shall be explicitly secured and verified. | N10: Pass | O10: 2026-10-28 | Q10: P0B-DB-001; package 0d30359ab5cdd4aa3577c33823de1bbc80a3d4f2; spec/meals/Phase 0B Recipe Persistence Design.md section 28; meals-db-final-manifest.json SHA256 4cbbc3eac24c13860d39ee3a0d8c6ae79c638cc5967d5274d1e7ea219091f8da; complete evidence in session b7458d86-6190-4718-8779-7c2b79a30630/files | R10: P0B-DB-001 Recipe foundation scope only. Captured production catalog and synthetic SQL SET ROLE/claim evidence, not live JWT/API authentication, owner application UAT or Recipe UI evidence. Future Meals objects require their own verification. No deployment blocker observed; blocker classification field is unchanged. Reversal prepared, not executed; test-only transaction rollback is not migration reversal. Explicit table/column/function ACLs passed; source and catalog do not rely on defaults.
B11: ARCH-012-T01 | C11: ARCH-012 | D11: 0 | E11: Architecture & Security | F11: ARCH | G11: Both | H11: COPILOT | I11: Local/Test | J11: Verify: browser-accessible Meals tables shall use explicit RLS and operation-specific owner policies. | K11: Use the identity/environment required by the test; production-changing actions require separate authorization. | L11: 1. Verify the behavior through the application using the specified identity. 2. Independently attempt the corresponding Supabase data/API operation using the same authorization context. 3. Confirm both layers produce the expected allow/deny result. 4. Capture evidence. | M11: Browser-accessible Meals tables shall use explicit RLS and operation-specific owner policies. | N11: Not Built
B12: ARCH-013-T01 | C12: ARCH-013 | D12: 0 | E12: Architecture & Security | F12: ARCH | G12: Both | H12: COPILOT | I12: Local/Test | J12: Verify: direct RLS-protected table operations are preferred where sufficient; RPCs shall not be introduced merely as CRUD wrappers. | K12: Use the identity/environment required by the test; production-changing actions require separate authorization. | L12: 1. Verify the behavior through the application using the specified identity. 2. Independently attempt the corresponding Supabase data/API operation using the same authorization context. 3. Confirm both layers produce the expected allow/deny result. 4. Capture evidence. | M12: Direct RLS-protected table operations are preferred where sufficient; RPCs shall not be introduced merely as CRUD wrappers. | N12: Not Built
B13: ARCH-014-T01 | C13: ARCH-014 | D13: 0 | E13: Architecture & Security | F13: ARCH | G13: Both | H13: COPILOT | I13: Local/Test | J13: Verify: any application-callable PostgreSQL function shall prefer SECURITY INVOKER; SECURITY DEFINER requires separate explicit security review before implementation. | K13: Use the identity/environment required by the test; production-changing actions require separate authorization. | L13: 1. Arrange the preconditions. 2. Perform the user/database action described by the requirement. 3. Observe the result. 4. Compare the observed result with Expected Result. | M13: Any application-callable PostgreSQL function shall prefer SECURITY INVOKER; SECURITY DEFINER requires separate explicit security review before implementation. | N13: Not Built
B14: SEC-TST-001-T01 | C14: SEC-TST-001 | D14: 0 | E14: Security Verification | F14: TEST | G14: Both | H14: COPILOT | I14: Local/Test | J14: Verify: logged out / anon shall be unable to retrieve private Meals data. | K14: Use the identity/environment required by the test; production-changing actions require separate authorization. | L14: 1. Sign out. 2. Open Meals/private data surfaces. 3. Attempt a direct private-data read through the application/test harness. | M14: Logged out / anon shall be unable to retrieve private Meals data. | N14: Not Built
B15: SEC-TST-002-T01 | C15: SEC-TST-002 | D15: 0 | E15: Security Verification | F15: TEST | G15: Both | H15: COPILOT | I15: Local/Test | J15: Verify: logged out / anon shall be unable to perform Meals mutations. | K15: Use the identity/environment required by the test; production-changing actions require separate authorization. | L15: 1. Arrange the preconditions. 2. Perform the user/database action described by the requirement. 3. Observe the result. 4. Compare the observed result with Expected Result. | M15: Logged out / anon shall be unable to perform Meals mutations. | N15: Not Built
B16: SEC-TST-003-T01 | C16: SEC-TST-003 | D16: 0 | E16: Security Verification | F16: TEST | G16: Both | H16: COPILOT | I16: Local/Test | J16: Verify: logged out / anon shall be unable to invoke private Meals RPCs, if any exist. | K16: Use the identity/environment required by the test; production-changing actions require separate authorization. | L16: 1. Arrange the preconditions. 2. Perform the user/database action described by the requirement. 3. Observe the result. 4. Compare the observed result with Expected Result. | M16: Logged out / anon shall be unable to invoke private Meals RPCs, if any exist. | N16: Not Built
B17: SEC-TST-004-T01 | C17: SEC-TST-004 | D17: 0 | E17: Security Verification | F17: TEST | G17: Both | H17: COPILOT | I17: Local/Test | J17: Verify: the authenticated designated owner shall succeed for each intended read/create/update/delete operation exposed by the implemented Meals UI. | K17: Use the identity/environment required by the test; production-changing actions require separate authorization. | L17: 1. Arrange the preconditions. 2. Perform the user/database action described by the requirement. 3. Observe the result. 4. Compare the observed result with Expected Result. | M17: The authenticated designated owner shall succeed for each intended read/create/update/delete operation exposed by the implemented Meals UI. | N17: Not Built
B18: SEC-TST-005-T01 | C18: SEC-TST-005 | D18: 0 | E18: Security Verification | F18: TEST | G18: Both | H18: COPILOT | I18: Local/Test | J18: Verify: a synthetic authenticated non-owner UUID shall be denied owner Meals data access and mutations. | K18: Use the identity/environment required by the test; production-changing actions require separate authorization. | L18: 1. Verify the behavior through the application using the specified identity. 2. Independently attempt the corresponding Supabase data/API operation using the same authorization context. 3. Confirm both layers produce the expected allow/deny result. 4. Capture evidence. | M18: A synthetic authenticated non-owner UUID shall be denied owner Meals data access and mutations. | N18: Not Built
